<sdf version='1.7'>
  <world name='default'>
    <gui fullscreen='0'>
      <camera name='user_camera'>
        <pose>15.514 3.96288 9.00823 0 0.327999 2.97919</pose>
        <view_controller>orbit</view_controller>
        <projection_type>perspective</projection_type>
      </camera>
    </gui>
    <scene>
      <grid>0</grid>
      <origin_visual>0</origin_visual>
      <ambient>0.592 0.624 0.635 1</ambient>
      <sky>
        <clouds>
          <speed>12</speed>
        </clouds>
      </sky>
      <background>0.35 0.35 0.35 1</background>
      <shadows>1</shadows>
    </scene>
    <physics name='default_physics' default='0' type='ode'>
      <ode>
        <solver>
          <type>quick</type>
          <iters>10</iters>
          <sor>1.3</sor>
          <use_dynamic_moi_rescaling>0</use_dynamic_moi_rescaling>
        </solver>
        <constraints>
          <cfm>0</cfm>
          <erp>0.2</erp>
          <contact_max_correcting_vel>100</contact_max_correcting_vel>
          <contact_surface_layer>0.001</contact_surface_layer>
        </constraints>
      </ode>
      <max_step_size>0.004</max_step_size>
      <real_time_factor>1</real_time_factor>
      <real_time_update_rate>250</real_time_update_rate>
    </physics>
    <light name='sun' type='directional'>
      <pose>0 0 1000 0 -0 0</pose>
      <cast_shadows>1</cast_shadows>
      <diffuse>0.8 0.8 0.8 1</diffuse>
      <specular>0.5 0.5 0.5 1</specular>
      <attenuation>
        <range>1000</range>
        <constant>0.9</constant>
        <linear>0.01</linear>
        <quadratic>0.001</quadratic>
      </attenuation>
      <direction>-0.5 0.1 -0.4</direction>
      <spot>
        <inner_angle>0</inner_angle>
        <outer_angle>0</outer_angle>
        <falloff>0</falloff>
      </spot>
    </light>
    <model name='ground_plane'>
      <static>1</static>
      <link name='link'>
        <collision name='collision'>
          <geometry>
            <plane>
              <normal>0 0 1</normal>
              <size>100 100</size>
            </plane>
          </geometry>
          <max_contacts>10</max_contacts>
          <surface>
            <contact>
              <ode/>
            </contact>
            <bounce/>
            <friction>
              <torsional>
                <ode/>
              </torsional>
              <ode/>
            </friction>
          </surface>
          <friction>
            <ode>
              <mu>100</mu>
              <mu2>50</mu2>
            </ode>
            <torsional>
              <ode/>
            </torsional>
          </friction>
          <contact>
            <ode/>
          </contact>
          <bounce/>
        </collision>
        <self_collide>0</self_collide>
        <enable_wind>0</enable_wind>
        <kinematic>0</kinematic>
      </link>
    </model>
    <model name='city_terrain_1'>
      <static>1</static>
      <link name='link'>
        <pose>0 0 -5 0 -0 0</pose>
        <collision name='collision'>
          <geometry>
            <plane>
              <normal>0 0 1</normal>
              <size>500 500</size>
            </plane>
          </geometry>
          <max_contacts>10</max_contacts>
          <surface>
            <contact>
              <ode/>
            </contact>
            <bounce/>
            <friction>
              <torsional>
                <ode/>
              </torsional>
              <ode/>
            </friction>
          </surface>
          <contact>
            <ode>
              <kp>1e+06</kp>
              <kd>100</kd>
              <max_vel>1</max_vel>
              <min_depth>0</min_depth>
            </ode>
          </contact>
          <friction>
            <ode>
              <mu>100</mu>
              <mu2>50</mu2>
            </ode>
            <torsional>
              <ode/>
            </torsional>
          </friction>
          <bounce/>
        </collision>
        <visual name='visual'>
          <geometry>
            <heightmap>
              <use_terrain_paging>0</use_terrain_paging>
              <texture>
                <diffuse>model://ocean/materials/textures/soil_sand_0045_01.jpg</diffuse>
                <normal>file://media/materials/textures/flat_normal.png</normal>
                <size>10</size>
              </texture>
              <blend>
                <min_height>0</min_height>
                <fade_dist>1.5</fade_dist>
              </blend>
              <texture>
                <diffuse>model://ocean/materials/textures/soil_sand_0045_01.jpg</diffuse>
                <normal>file://media/materials/textures/flat_normal.png</normal>
                <size>10</size>
              </texture>
              <blend>
                <min_height>2.5</min_height>
                <fade_dist>5</fade_dist>
              </blend>
              <texture>
                <diffuse>model://city_terrain/materials/textures/forest.jpg</diffuse>
                <normal>file://media/materials/textures/flat_normal.png</normal>
                <size>10</size>
              </texture>
              <uri>model://city_terrain/materials/textures/city_terrain.jpg</uri>
              <size>500 500 75</size>
              <pos>40 -20 -5</pos>
            </heightmap>
          </geometry>
        </visual>
        <self_collide>0</self_collide>
        <enable_wind>0</enable_wind>
        <kinematic>0</kinematic>
      </link>
      <pose>0 0 0 0 -0 0</pose>
    </model>
    <model name='ocean_2'>
      <static>1</static>
      <link name='ocean_link'>
        <visual name='ocean_visual1'>
          <pose>0 0 0 0 -0 0</pose>
          <geometry>
            <mesh>
              <uri>model://ocean/mesh.dae</uri>
              <scale>0.5 0.5 0.5</scale>
            </mesh>
          </geometry>
          <material>
            <script>
              <uri>model://ocean/materials/scripts/ocean.material</uri>
              <name>Waves_GLSL</name>
            </script>
          </material>
        </visual>
        <visual name='ocean_below'>
          <pose>0 0 0 0 -0 0</pose>
          <geometry>
            <mesh>
              <uri>model://ocean/mesh_below.dae</uri>
              <scale>0.5 0.5 0.5</scale>
            </mesh>
          </geometry>
          <material>
            <script>
              <uri>model://ocean/materials/scripts/ocean.material</uri>
              <name>Waves_GLSL</name>
            </script>
          </material>
        </visual>
        <visual name='north'>
          <pose>250 0 -3.5 3.14159 -1.57079 3.14159</pose>
          <geometry>
            <plane>
              <normal>0 0 1</normal>
              <size>7 500</size>
            </plane>
          </geometry>
          <material>
            <script>
              <uri>model://ocean/materials/scripts/ocean.material</uri>
              <name>Seabox</name>
            </script>
          </material>
        </visual>
        <visual name='south'>
          <pose>-250 0 -3.5 3.14159 1.57079 3.14159</pose>
          <geometry>
            <plane>
              <normal>0 0 1</normal>
              <size>7 500</size>
            </plane>
          </geometry>
          <material>
            <script>
              <uri>model://ocean/materials/scripts/ocean.material</uri>
              <name>Seabox</name>
            </script>
          </material>
        </visual>
        <visual name='west'>
          <pose>0 250 -3.5 1.5708 -0 0</pose>
          <geometry>
            <plane>
              <normal>0 0 1</normal>
              <size>500 7</size>
            </plane>
          </geometry>
          <material>
            <script>
              <uri>model://ocean/materials/scripts/ocean.material</uri>
              <name>Seabox</name>
            </script>
          </material>
        </visual>
        <visual name='east'>
          <pose>0 -250 -3.5 -1.5708 0 0</pose>
          <geometry>
            <plane>
              <normal>0 0 1</normal>
              <size>500 7</size>
            </plane>
          </geometry>
          <material>
            <script>
              <uri>model://ocean/materials/scripts/ocean.material</uri>
              <name>Seabox</name>
            </script>
          </material>
        </visual>
        <self_collide>0</self_collide>
        <enable_wind>0</enable_wind>
        <kinematic>0</kinematic>
      </link>
      <pose>40 -20 -2 0 -0 0</pose>
    </model>
    <road name='road_y_1'>
      <width>7.4</width>
      <point>-45 -48.7 0.01</point>
      <point>-45 49.2 0.01</point>
    </road>
    <road name='road_y_2'>
      <width>7.4</width>
      <point>-15 -48.7 0.01</point>
      <point>-15 49.2 0.01</point>
      <material>
        <script>
          <uri>file://media/materials/scripts/gazebo.material</uri>
          <name>Gazebo/Residential</name>
        </script>
      </material>
    </road>
    <road name='road_y_3'>
      <width>7.4</width>
      <point>45 -48.7 0.01</point>
      <point>45 49.2 0.01</point>
      <material>
        <script>
          <uri>file://media/materials/scripts/gazebo.material</uri>
          <name>Gazebo/Residential</name>
        </script>
      </material>
    </road>
    <road name='road_y_4'>
      <width>7.4</width>
      <point>110 -48.7 0.01</point>
      <point>110 49.2 0.01</point>
      <material>
        <script>
          <uri>file://media/materials/scripts/gazebo.material</uri>
          <name>Gazebo/Residential</name>
        </script>
      </material>
    </road>
    <road name='road_y_5'>
      <width>7.4</width>
      <point>120 -48.7 0.01</point>
      <point>120 49.2 0.01</point>
    </road>
    <road name='road_x_1'>
      <width>8.4</width>
      <point>-41.3 -45 0.015</point>
      <point>116.3 -45 0.015</point>
    </road>
    <road name='road_x_2'>
      <width>8.4</width>
      <point>-41.3 0 0.015</point>
      <point>116.3 0 0.015</point>
      <material>
        <script>
          <uri>file://media/materials/scripts/gazebo.material</uri>
          <name>Gazebo/Residential</name>
        </script>
      </material>
    </road>
    <road name='road_x_3'>
      <width>8.4</width>
      <point>-41.3 45 0.015</point>
      <point>116.3 45 0.015</point>
    </road>
    <road name='sandy_path'>
      <width>17.9</width>
      <point>-73 -47.96 0.01</point>
      <point>-73 2.96 0.01</point>
      <material>
        <script>
          <uri>file://media/materials/scripts/gazebo.material</uri>
          <name>Gazebo/Residential</name>
        </script>
      </material>
    </road>
    <gravity>0 0 -9.8</gravity>
    <magnetic_field>6e-06 2.3e-05 -4.2e-05</magnetic_field>
    <atmosphere type='adiabatic'/>
    <wind/>
    <spherical_coordinates>
      <surface_model>EARTH_WGS84</surface_model>
      <latitude_deg>0</latitude_deg>
      <longitude_deg>0</longitude_deg>
      <elevation>0</elevation>
      <heading_deg>0</heading_deg>
    </spherical_coordinates>
    <state world_name='default'>
      <sim_time>2075 788000000</sim_time>
      <real_time>325 451793822</real_time>
      <wall_time>1714833350 126778378</wall_time>
      <iterations>80903</iterations>
      <model name='casual_female'>
        <pose>-26.902 13.6572 0 0 -0 0</pose>
        <scale>1 1 1</scale>
        <link name='link'>
          <pose>-26.902 13.6572 0 0 -0 0</pose>
          <velocity>0 0 0 0 -0 0</velocity>
          <acceleration>0 0 0 0 -0 0</acceleration>
          <wrench>0 0 0 0 -0 0</wrench>
        </link>
      </model>
      <model name='city_terrain_1'>
        <pose>0 0 0 0 -0 0</pose>
        <scale>1 1 1</scale>
        <link name='link'>
          <pose>0 0 -5 0 -0 0</pose>
          <velocity>0 0 0 0 -0 0</velocity>
          <acceleration>0 0 0 0 -0 0</acceleration>
          <wrench>0 0 0 0 -0 0</wrench>
        </link>
      </model>
      <model name='ground_plane'>
        <pose>0 0 0 0 -0 0</pose>
        <scale>1 1 1</scale>
        <link name='link'>
          <pose>0 0 0 0 -0 0</pose>
          <velocity>0 0 0 0 -0 0</velocity>
          <acceleration>0 0 0 0 -0 0</acceleration>
          <wrench>0 0 0 0 -0 0</wrench>
        </link>
      </model>
 
      <model name='ocean_2'>
        <pose>40 -20 -2 0 -0 0</pose>
        <scale>1 1 1</scale>
        <link name='ocean_link'>
          <pose>40 -20 -2 0 -0 0</pose>
          <velocity>0 0 0 0 -0 0</velocity>
          <acceleration>0 0 0 0 -0 0</acceleration>
          <wrench>0 0 0 0 -0 0</wrench>
        </link>
      </model>
      <light name='sun'>
        <pose>0 0 1000 0 -0 0</pose>
      </light>
    </state>
    <model name='casual_female'>
      <static>1</static>
      <link name='link'>
        <collision name='box'>
          <pose>0 0 0.9 0 -0 0</pose>
          <geometry>
            <box>
              <size>0.76 0.33 1.77</size>
            </box>
          </geometry>
          <max_contacts>10</max_contacts>
          <surface>
            <contact>
              <ode/>
            </contact>
            <bounce/>
            <friction>
              <torsional>
                <ode/>
              </torsional>
              <ode/>
            </friction>
          </surface>
          <contact>
            <ode/>
          </contact>
          <bounce/>
          <friction>
            <torsional>
              <ode/>
            </torsional>
            <ode/>
          </friction>
        </collision>
        <visual name='visual'>
          <pose>0 0 0.02 0.04 -0 0</pose>
          <geometry>
            <mesh>
              <uri>model://casual_female/meshes/casual_female.dae</uri>
            </mesh>
          </geometry>
        </visual>
        <self_collide>0</self_collide>
        <enable_wind>0</enable_wind>
        <kinematic>0</kinematic>
      </link>
      <pose>-26.902 13.6572 0 0 -0 0</pose>
    </model>
    <gravity>0 0 -9.8066</gravity>
    <magnetic_field>6e-06 2.3e-05 -4.2e-05</magnetic_field>
    <model name='iris_0'>
      <link name='base_link'>
        <pose>0 0 0 0 -0 0</pose>
        <inertial>
          <pose>0 0 0 0 -0 0</pose>
          <mass>1.5</mass>
          <inertia>
            <ixx>0.029125</ixx>
            <ixy>0</ixy>
            <ixz>0</ixz>
            <iyy>0.029125</iyy>
            <iyz>0</iyz>
            <izz>0.055225</izz>
          </inertia>
        </inertial>
        <collision name='base_link_inertia_collision'>
          <pose>0 0 0 0 -0 0</pose>
          <geometry>
            <box>
              <size>0.47 0.47 0.11</size>
            </box>
          </geometry>
          <surface>
            <contact>
              <ode>
                <min_depth>0.001</min_depth>
                <max_vel>0</max_vel>
              </ode>
            </contact>
            <friction>
              <ode/>
              <torsional>
                <ode/>
              </torsional>
            </friction>
            <bounce/>
          </surface>
          <max_contacts>10</max_contacts>
        </collision>
        <visual name='base_link_inertia_visual'>
          <pose>0 0 0 0 -0 0</pose>
          <geometry>
            <mesh>
              <scale>1 1 1</scale>
              <uri>model://iris/meshes/iris.stl</uri>
            </mesh>
          </geometry>
          <material>
            <script>
              <name>Gazebo/DarkGrey</name>
              <uri>file://media/materials/scripts/gazebo.material</uri>
            </script>
          </material>
        </visual>
        <gravity>1</gravity>
        <velocity_decay/>
        <self_collide>0</self_collide>
        <enable_wind>0</enable_wind>
        <kinematic>0</kinematic>
      </link>
      <link name='/imu_link'>
        <pose>0 0 0 0 -0 0</pose>
        <inertial>
          <pose>0 0 0 0 -0 0</pose>
          <mass>0.015</mass>
          <inertia>
            <ixx>1e-05</ixx>
            <ixy>0</ixy>
            <ixz>0</ixz>
            <iyy>1e-05</iyy>
            <iyz>0</iyz>
            <izz>1e-05</izz>
          </inertia>
        </inertial>
        <self_collide>0</self_collide>
        <enable_wind>0</enable_wind>
        <kinematic>0</kinematic>
      </link>
      <joint name='/imu_joint' type='revolute'>
        <child>/imu_link</child>
        <parent>base_link</parent>
        <axis>
          <xyz expressed_in='__model__'>1 0 0</xyz>
          <limit>
            <lower>0</lower>
            <upper>0</upper>
            <effort>0</effort>
            <velocity>0</velocity>
          </limit>
          <dynamics>
            <spring_reference>0</spring_reference>
            <spring_stiffness>0</spring_stiffness>
          </dynamics>
        </axis>
      </joint>
      <link name='rotor_0'>
        <pose>0.13 -0.22 0.023 0 -0 0</pose>
        <inertial>
          <pose>0 0 0 0 -0 0</pose>
          <mass>0.005</mass>
          <inertia>
            <ixx>9.75e-07</ixx>
            <ixy>0</ixy>
            <ixz>0</ixz>
            <iyy>0.000273104</iyy>
            <iyz>0</iyz>
            <izz>0.000274004</izz>
          </inertia>
        </inertial>
        <collision name='rotor_0_collision'>
          <pose>0 0 0 0 -0 0</pose>
          <geometry>
            <cylinder>
              <length>0.005</length>
              <radius>0.128</radius>
            </cylinder>
          </geometry>
          <surface>
            <contact>
              <ode/>
            </contact>
            <friction>
              <ode/>
              <torsional>
                <ode/>
              </torsional>
            </friction>
            <bounce/>
          </surface>
          <max_contacts>10</max_contacts>
        </collision>
        <visual name='rotor_0_visual'>
          <pose>0 0 0 0 -0 0</pose>
          <geometry>
            <mesh>
              <scale>1 1 1</scale>
              <uri>model://iris/meshes/iris_prop_ccw.dae</uri>
            </mesh>
          </geometry>
          <material>
            <script>
              <name>Gazebo/Blue</name>
              <uri>file://media/materials/scripts/gazebo.material</uri>
            </script>
          </material>
        </visual>
        <gravity>1</gravity>
        <velocity_decay/>
        <self_collide>0</self_collide>
        <enable_wind>0</enable_wind>
        <kinematic>0</kinematic>
      </link>
      <joint name='rotor_0_joint' type='revolute'>
        <child>rotor_0</child>
        <parent>base_link</parent>
        <axis>
          <xyz expressed_in='__model__'>0 0 1</xyz>
          <limit>
            <lower>-1e+16</lower>
            <upper>1e+16</upper>
          </limit>
          <dynamics>
            <spring_reference>0</spring_reference>
            <spring_stiffness>0</spring_stiffness>
          </dynamics>
        </axis>
      </joint>
      <link name='rotor_1'>
        <pose>-0.13 0.2 0.023 0 -0 0</pose>
        <inertial>
          <pose>0 0 0 0 -0 0</pose>
          <mass>0.005</mass>
          <inertia>
            <ixx>9.75e-07</ixx>
            <ixy>0</ixy>
            <ixz>0</ixz>
            <iyy>0.000273104</iyy>
            <iyz>0</iyz>
            <izz>0.000274004</izz>
          </inertia>
        </inertial>
        <collision name='rotor_1_collision'>
          <pose>0 0 0 0 -0 0</pose>
          <geometry>
            <cylinder>
              <length>0.005</length>
              <radius>0.128</radius>
            </cylinder>
          </geometry>
          <surface>
            <contact>
              <ode/>
            </contact>
            <friction>
              <ode/>
              <torsional>
                <ode/>
              </torsional>
            </friction>
            <bounce/>
          </surface>
          <max_contacts>10</max_contacts>
        </collision>
        <visual name='rotor_1_visual'>
          <pose>0 0 0 0 -0 0</pose>
          <geometry>
            <mesh>
              <scale>1 1 1</scale>
              <uri>model://iris/meshes/iris_prop_ccw.dae</uri>
            </mesh>
          </geometry>
          <material>
            <script>
              <name>Gazebo/DarkGrey</name>
              <uri>file://media/materials/scripts/gazebo.material</uri>
            </script>
          </material>
        </visual>
        <gravity>1</gravity>
        <velocity_decay/>
        <self_collide>0</self_collide>
        <enable_wind>0</enable_wind>
        <kinematic>0</kinematic>
      </link>
      <joint name='rotor_1_joint' type='revolute'>
        <child>rotor_1</child>
        <parent>base_link</parent>
        <axis>
          <xyz expressed_in='__model__'>0 0 1</xyz>
          <limit>
            <lower>-1e+16</lower>
            <upper>1e+16</upper>
          </limit>
          <dynamics>
            <spring_reference>0</spring_reference>
            <spring_stiffness>0</spring_stiffness>
          </dynamics>
        </axis>
      </joint>
      <link name='rotor_2'>
        <pose>0.13 0.22 0.023 0 -0 0</pose>
        <inertial>
          <pose>0 0 0 0 -0 0</pose>
          <mass>0.005</mass>
          <inertia>
            <ixx>9.75e-07</ixx>
            <ixy>0</ixy>
            <ixz>0</ixz>
            <iyy>0.000273104</iyy>
            <iyz>0</iyz>
            <izz>0.000274004</izz>
          </inertia>
        </inertial>
        <collision name='rotor_2_collision'>
          <pose>0 0 0 0 -0 0</pose>
          <geometry>
            <cylinder>
              <length>0.005</length>
              <radius>0.128</radius>
            </cylinder>
          </geometry>
          <surface>
            <contact>
              <ode/>
            </contact>
            <friction>
              <ode/>
              <torsional>
                <ode/>
              </torsional>
            </friction>
            <bounce/>
          </surface>
          <max_contacts>10</max_contacts>
        </collision>
        <visual name='rotor_2_visual'>
          <pose>0 0 0 0 -0 0</pose>
          <geometry>
            <mesh>
              <scale>1 1 1</scale>
              <uri>model://iris/meshes/iris_prop_cw.dae</uri>
            </mesh>
          </geometry>
          <material>
            <script>
              <name>Gazebo/Blue</name>
              <uri>file://media/materials/scripts/gazebo.material</uri>
            </script>
          </material>
        </visual>
        <gravity>1</gravity>
        <velocity_decay/>
        <self_collide>0</self_collide>
        <enable_wind>0</enable_wind>
        <kinematic>0</kinematic>
      </link>
      <joint name='rotor_2_joint' type='revolute'>
        <child>rotor_2</child>
        <parent>base_link</parent>
        <axis>
          <xyz expressed_in='__model__'>0 0 1</xyz>
          <limit>
            <lower>-1e+16</lower>
            <upper>1e+16</upper>
          </limit>
          <dynamics>
            <spring_reference>0</spring_reference>
            <spring_stiffness>0</spring_stiffness>
          </dynamics>
        </axis>
      </joint>
      <link name='rotor_3'>
        <pose>-0.13 -0.2 0.023 0 -0 0</pose>
        <inertial>
          <pose>0 0 0 0 -0 0</pose>
          <mass>0.005</mass>
          <inertia>
            <ixx>9.75e-07</ixx>
            <ixy>0</ixy>
            <ixz>0</ixz>
            <iyy>0.000273104</iyy>
            <iyz>0</iyz>
            <izz>0.000274004</izz>
          </inertia>
        </inertial>
        <collision name='rotor_3_collision'>
          <pose>0 0 0 0 -0 0</pose>
          <geometry>
            <cylinder>
              <length>0.005</length>
              <radius>0.128</radius>
            </cylinder>
          </geometry>
          <surface>
            <contact>
              <ode/>
            </contact>
            <friction>
              <ode/>
              <torsional>
                <ode/>
              </torsional>
            </friction>
            <bounce/>
          </surface>
          <max_contacts>10</max_contacts>
        </collision>
        <visual name='rotor_3_visual'>
          <pose>0 0 0 0 -0 0</pose>
          <geometry>
            <mesh>
              <scale>1 1 1</scale>
              <uri>model://iris/meshes/iris_prop_cw.dae</uri>
            </mesh>
          </geometry>
          <material>
            <script>
              <name>Gazebo/DarkGrey</name>
              <uri>file://media/materials/scripts/gazebo.material</uri>
            </script>
          </material>
        </visual>
        <gravity>1</gravity>
        <velocity_decay/>
        <self_collide>0</self_collide>
        <enable_wind>0</enable_wind>
        <kinematic>0</kinematic>
      </link>
      <joint name='rotor_3_joint' type='revolute'>
        <child>rotor_3</child>
        <parent>base_link</parent>
        <axis>
          <xyz expressed_in='__model__'>0 0 1</xyz>
          <limit>
            <lower>-1e+16</lower>
            <upper>1e+16</upper>
          </limit>
          <dynamics>
            <spring_reference>0</spring_reference>
            <spring_stiffness>0</spring_stiffness>
          </dynamics>
        </axis>
      </joint>
      <plugin name='rosbag' filename='libgazebo_multirotor_base_plugin.so'>
        <robotNamespace/>
        <linkName>base_link</linkName>
        <rotorVelocitySlowdownSim>10</rotorVelocitySlowdownSim>
      </plugin>
      <plugin name='front_right_motor_model' filename='libgazebo_motor_model.so'>
        <robotNamespace/>
        <jointName>rotor_0_joint</jointName>
        <linkName>rotor_0</linkName>
        <turningDirection>ccw</turningDirection>
        <timeConstantUp>0.0125</timeConstantUp>
        <timeConstantDown>0.025</timeConstantDown>
        <maxRotVelocity>1100</maxRotVelocity>
        <motorConstant>5.84e-06</motorConstant>
        <momentConstant>0.06</momentConstant>
        <commandSubTopic>/gazebo/command/motor_speed</commandSubTopic>
        <motorNumber>0</motorNumber>
        <rotorDragCoefficient>0.000175</rotorDragCoefficient>
        <rollingMomentCoefficient>1e-06</rollingMomentCoefficient>
        <motorSpeedPubTopic>/motor_speed/0</motorSpeedPubTopic>
        <rotorVelocitySlowdownSim>10</rotorVelocitySlowdownSim>
      </plugin>
      <plugin name='back_left_motor_model' filename='libgazebo_motor_model.so'>
        <robotNamespace/>
        <jointName>rotor_1_joint</jointName>
        <linkName>rotor_1</linkName>
        <turningDirection>ccw</turningDirection>
        <timeConstantUp>0.0125</timeConstantUp>
        <timeConstantDown>0.025</timeConstantDown>
        <maxRotVelocity>1100</maxRotVelocity>
        <motorConstant>5.84e-06</motorConstant>
        <momentConstant>0.06</momentConstant>
        <commandSubTopic>/gazebo/command/motor_speed</commandSubTopic>
        <motorNumber>1</motorNumber>
        <rotorDragCoefficient>0.000175</rotorDragCoefficient>
        <rollingMomentCoefficient>1e-06</rollingMomentCoefficient>
        <motorSpeedPubTopic>/motor_speed/1</motorSpeedPubTopic>
        <rotorVelocitySlowdownSim>10</rotorVelocitySlowdownSim>
      </plugin>
      <plugin name='front_left_motor_model' filename='libgazebo_motor_model.so'>
        <robotNamespace/>
        <jointName>rotor_2_joint</jointName>
        <linkName>rotor_2</linkName>
        <turningDirection>cw</turningDirection>
        <timeConstantUp>0.0125</timeConstantUp>
        <timeConstantDown>0.025</timeConstantDown>
        <maxRotVelocity>1100</maxRotVelocity>
        <motorConstant>5.84e-06</motorConstant>
        <momentConstant>0.06</momentConstant>
        <commandSubTopic>/gazebo/command/motor_speed</commandSubTopic>
        <motorNumber>2</motorNumber>
        <rotorDragCoefficient>0.000175</rotorDragCoefficient>
        <rollingMomentCoefficient>1e-06</rollingMomentCoefficient>
        <motorSpeedPubTopic>/motor_speed/2</motorSpeedPubTopic>
        <rotorVelocitySlowdownSim>10</rotorVelocitySlowdownSim>
      </plugin>
      <plugin name='back_right_motor_model' filename='libgazebo_motor_model.so'>
        <robotNamespace/>
        <jointName>rotor_3_joint</jointName>
        <linkName>rotor_3</linkName>
        <turningDirection>cw</turningDirection>
        <timeConstantUp>0.0125</timeConstantUp>
        <timeConstantDown>0.025</timeConstantDown>
        <maxRotVelocity>1100</maxRotVelocity>
        <motorConstant>5.84e-06</motorConstant>
        <momentConstant>0.06</momentConstant>
        <commandSubTopic>/gazebo/command/motor_speed</commandSubTopic>
        <motorNumber>3</motorNumber>
        <rotorDragCoefficient>0.000175</rotorDragCoefficient>
        <rollingMomentCoefficient>1e-06</rollingMomentCoefficient>
        <motorSpeedPubTopic>/motor_speed/3</motorSpeedPubTopic>
        <rotorVelocitySlowdownSim>10</rotorVelocitySlowdownSim>
      </plugin>
      <frame name='gps0::__model__' attached_to='gps0::link'>
        <pose relative_to='__model__'>0.1 0 0 0 -0 0</pose>
      </frame>
      <link name='gps0::link'>
        <pose relative_to='gps0::__model__'>0 0 0 0 -0 0</pose>
        <inertial>
          <pose>0 0 0 0 -0 0</pose>
          <mass>0.015</mass>
          <inertia>
            <ixx>1e-05</ixx>
            <ixy>0</ixy>
            <ixz>0</ixz>
            <iyy>1e-05</iyy>
            <iyz>0</iyz>
            <izz>1e-05</izz>
          </inertia>
        </inertial>
        <visual name='visual'>
          <geometry>
            <cylinder>
              <radius>0.01</radius>
              <length>0.002</length>
            </cylinder>
          </geometry>
          <material>
            <script>
              <name>Gazebo/Black</name>
              <uri>__default__</uri>
            </script>
          </material>
        </visual>
        <sensor name='gps' type='gps'>
          <pose>0 0 0 0 -0 0</pose>
          <update_rate>5</update_rate>
          <always_on>1</always_on>
          <visualize>0</visualize>
          <plugin name='gps_plugin' filename='libgazebo_gps_plugin.so'>
            <robotNamespace/>
            <gpsNoise>1</gpsNoise>
            <gpsXYRandomWalk>2.0</gpsXYRandomWalk>
            <gpsZRandomWalk>4.0</gpsZRandomWalk>
            <gpsXYNoiseDensity>2.0e-4</gpsXYNoiseDensity>
            <gpsZNoiseDensity>4.0e-4</gpsZNoiseDensity>
            <gpsVXYNoiseDensity>0.2</gpsVXYNoiseDensity>
            <gpsVZNoiseDensity>0.4</gpsVZNoiseDensity>
          </plugin>
          <gps/>
        </sensor>
        <self_collide>0</self_collide>
        <enable_wind>0</enable_wind>
        <kinematic>0</kinematic>
      </link>
      <joint name='gps0_joint' type='fixed'>
        <child>gps0::link</child>
        <parent>base_link</parent>
      </joint>
      <plugin name='groundtruth_plugin' filename='libgazebo_groundtruth_plugin.so'>
        <robotNamespace/>
      </plugin>
      <plugin name='magnetometer_plugin' filename='libgazebo_magnetometer_plugin.so'>
        <robotNamespace/>
        <pubRate>100</pubRate>
        <noiseDensity>0.0004</noiseDensity>
        <randomWalk>6.4e-06</randomWalk>
        <biasCorrelationTime>600</biasCorrelationTime>
        <magTopic>/mag</magTopic>
      </plugin>
      <plugin name='barometer_plugin' filename='libgazebo_barometer_plugin.so'>
        <robotNamespace/>
        <pubRate>50</pubRate>
        <baroTopic>/baro</baroTopic>
        <baroDriftPaPerSec>0</baroDriftPaPerSec>
      </plugin>
      <plugin name='mavlink_interface' filename='libgazebo_mavlink_interface.so'>
        <robotNamespace/>
        <imuSubTopic>/imu</imuSubTopic>
        <magSubTopic>/mag</magSubTopic>
        <baroSubTopic>/baro</baroSubTopic>
        <mavlink_addr>INADDR_ANY</mavlink_addr>
        <mavlink_udp_port>14560</mavlink_udp_port>
        <serialEnabled>0</serialEnabled>
        <serialDevice>/dev/ttyACM0</serialDevice>
        <baudRate>921600</baudRate>
        <qgc_addr>INADDR_ANY</qgc_addr>
        <qgc_udp_port>14550</qgc_udp_port>
        <sdk_addr>INADDR_ANY</sdk_addr>
        <sdk_udp_port>14540</sdk_udp_port>
        <hil_mode>0</hil_mode>
        <hil_state_level>0</hil_state_level>
        <send_vision_estimation>0</send_vision_estimation>
        <send_odometry>1</send_odometry>
        <enable_lockstep>1</enable_lockstep>
        <use_tcp>1</use_tcp>
        <motorSpeedCommandPubTopic>/gazebo/command/motor_speed</motorSpeedCommandPubTopic>
        <control_channels>
          <channel name='rotor1'>
            <input_index>0</input_index>
            <input_offset>0</input_offset>
            <input_scaling>1000</input_scaling>
            <zero_position_disarmed>0</zero_position_disarmed>
            <zero_position_armed>100</zero_position_armed>
            <joint_control_type>velocity</joint_control_type>
          </channel>
          <channel name='rotor2'>
            <input_index>1</input_index>
            <input_offset>0</input_offset>
            <input_scaling>1000</input_scaling>
            <zero_position_disarmed>0</zero_position_disarmed>
            <zero_position_armed>100</zero_position_armed>
            <joint_control_type>velocity</joint_control_type>
          </channel>
          <channel name='rotor3'>
            <input_index>2</input_index>
            <input_offset>0</input_offset>
            <input_scaling>1000</input_scaling>
            <zero_position_disarmed>0</zero_position_disarmed>
            <zero_position_armed>100</zero_position_armed>
            <joint_control_type>velocity</joint_control_type>
          </channel>
          <channel name='rotor4'>
            <input_index>3</input_index>
            <input_offset>0</input_offset>
            <input_scaling>1000</input_scaling>
            <zero_position_disarmed>0</zero_position_disarmed>
            <zero_position_armed>100</zero_position_armed>
            <joint_control_type>velocity</joint_control_type>
          </channel>
          <channel name='rotor5'>
            <input_index>4</input_index>
            <input_offset>1</input_offset>
            <input_scaling>324.6</input_scaling>
            <zero_position_disarmed>0</zero_position_disarmed>
            <zero_position_armed>0</zero_position_armed>
            <joint_control_type>velocity</joint_control_type>
            <joint_control_pid>
              <p>0.1</p>
              <i>0</i>
              <d>0</d>
              <iMax>0.0</iMax>
              <iMin>0.0</iMin>
              <cmdMax>2</cmdMax>
              <cmdMin>-2</cmdMin>
            </joint_control_pid>
            <joint_name>zephyr_delta_wing::propeller_joint</joint_name>
          </channel>
          <channel name='rotor6'>
            <input_index>5</input_index>
            <input_offset>0</input_offset>
            <input_scaling>0.524</input_scaling>
            <zero_position_disarmed>0</zero_position_disarmed>
            <zero_position_armed>0</zero_position_armed>
            <joint_control_type>position</joint_control_type>
            <joint_name>zephyr_delta_wing::flap_left_joint</joint_name>
            <joint_control_pid>
              <p>10.0</p>
              <i>0</i>
              <d>0</d>
              <iMax>0</iMax>
              <iMin>0</iMin>
              <cmdMax>20</cmdMax>
              <cmdMin>-20</cmdMin>
            </joint_control_pid>
          </channel>
          <channel name='rotor7'>
            <input_index>6</input_index>
            <input_offset>0</input_offset>
            <input_scaling>0.524</input_scaling>
            <zero_position_disarmed>0</zero_position_disarmed>
            <zero_position_armed>0</zero_position_armed>
            <joint_control_type>position</joint_control_type>
            <joint_name>zephyr_delta_wing::flap_right_joint</joint_name>
            <joint_control_pid>
              <p>10.0</p>
              <i>0</i>
              <d>0</d>
              <iMax>0</iMax>
              <iMin>0</iMin>
              <cmdMax>20</cmdMax>
              <cmdMin>-20</cmdMin>
            </joint_control_pid>
          </channel>
          <channel name='rotor8'>
            <input_index>7</input_index>
            <input_offset>0</input_offset>
            <input_scaling>0.524</input_scaling>
            <zero_position_disarmed>0</zero_position_disarmed>
            <zero_position_armed>0</zero_position_armed>
            <joint_control_type>position</joint_control_type>
          </channel>
        </control_channels>
        <mavlink_tcp_port>4560</mavlink_tcp_port>
      </plugin>
      <static>0</static>
      <plugin name='rotors_gazebo_imu_plugin' filename='libgazebo_imu_plugin.so'>
        <robotNamespace/>
        <linkName>/imu_link</linkName>
        <imuTopic>/imu</imuTopic>
        <gyroscopeNoiseDensity>0.00018665</gyroscopeNoiseDensity>
        <gyroscopeRandomWalk>3.8785e-05</gyroscopeRandomWalk>
        <gyroscopeBiasCorrelationTime>1000.0</gyroscopeBiasCorrelationTime>
        <gyroscopeTurnOnBiasSigma>0.0087</gyroscopeTurnOnBiasSigma>
        <accelerometerNoiseDensity>0.00186</accelerometerNoiseDensity>
        <accelerometerRandomWalk>0.006</accelerometerRandomWalk>
        <accelerometerBiasCorrelationTime>300.0</accelerometerBiasCorrelationTime>
        <accelerometerTurnOnBiasSigma>0.196</accelerometerTurnOnBiasSigma>
      </plugin>
      <frame name='realsense_camera::__model__' attached_to='realsense_camera::link'>
        <pose relative_to='__model__'>0.1 0 0 0 -0 0</pose>
      </frame>
      <link name='realsense_camera::link'>
        <inertial>
          <mass>0.0615752</mass>
          <inertia>
            <ixx>9.108e-05</ixx>
            <ixy>0</ixy>
            <ixz>0</ixz>
            <iyy>2.51e-06</iyy>
            <iyz>0</iyz>
            <izz>8.931e-05</izz>
          </inertia>
          <pose>0 0 0 0 -0 0</pose>
        </inertial>
        <self_collide>0</self_collide>
        <enable_wind>0</enable_wind>
        <kinematic>0</kinematic>
        <gravity>1</gravity>
        <visual name='visual'>
          <geometry>
            <mesh>
              <uri>model://realsense_camera/meshes/realsense_camera.dae</uri>
            </mesh>
          </geometry>
        </visual>
        <sensor name='imu_sensor' type='imu'>
          <always_on>1</always_on>
          <update_rate>500</update_rate>
          <visualize>1</visualize>
          <topic>imu_gazebo</topic>
          <plugin name='imu_plugin' filename='libgazebo_ros_imu_sensor.so'>
            <topicName>imu_gazebo</topicName>
            <bodyName>imu_link_stereo</bodyName>
            <updateRateHZ>500.0</updateRateHZ>
            <gaussianNoise>0.0</gaussianNoise>
            <xyzOffset>0 0 0</xyzOffset>
            <rpyOffset>0 0 0</rpyOffset>
            <frameName>imu_link_stereo</frameName>
            <gyroscopeNoiseDensity>0.0006</gyroscopeNoiseDensity>
            <gyroscopeRandomWalk>0.000003</gyroscopeRandomWalk>
            <gyroscopeTurnOnBiasSigma>0.03</gyroscopeTurnOnBiasSigma>
            <accelerometerNoiseDensity>0.002</accelerometerNoiseDensity>
            <accelerometerRandomWalk>0.00002</accelerometerRandomWalk>
            <accelerometerTurnOnBiasSigma>0.1</accelerometerTurnOnBiasSigma>
          </plugin>
          <pose>0 0 0.3 0 -0 0</pose>
          <imu/>
          <parent>realsense_camera::link</parent>
        </sensor>
        <sensor name='stereo' type='multicamera'>
          <always_on>1</always_on>
          <update_rate>30</update_rate>
          <visualize>0</visualize>
          <camera name='left'>
            <pose>0 0.06 0 0 -0 0</pose>
            <horizontal_fov>1.5708</horizontal_fov>
            <image>
              <width>752</width>
              <height>480</height>
              <format>R8G8B8</format>
            </image>
            <clip>
              <near>0.1</near>
              <far>300</far>
            </clip>
          </camera>
          <camera name='right'>
            <pose>0 -0.06 0 0 -0 0</pose>
            <horizontal_fov>1.5708</horizontal_fov>
            <image>
              <width>752</width>
              <height>480</height>
              <format>R8G8B8</format>
            </image>
            <clip>
              <near>0.1</near>
              <far>300</far>
            </clip>
          </camera>
          <plugin name='stereo_camera_controller' filename='libgazebo_ros_multicamera.so'>
            <robotNamespace/>
            <alwaysOn>1</alwaysOn>
            <updateRate>30</updateRate>
            <cameraName>/stereo_camera</cameraName>
            <imageTopicName>image_raw</imageTopicName>
            <cameraInfoTopicName>camera_info</cameraInfoTopicName>
            <frameName>stereo_camera_frame</frameName>
            <hackBaseline>0.12</hackBaseline>
            <Fx>376.0</Fx>
            <Fy>376.0</Fy>
            <Cx>376.0</Cx>
            <Cy>240.0</Cy>
            <distortionK1>-0.1</distortionK1>
            <distortionK2>0.01</distortionK2>
            <distortionK3>0.0</distortionK3>
            <distortionT1>5e-5</distortionT1>
            <distortionT2>-1e-4</distortionT2>
          </plugin>
        </sensor>
        <sensor name='depth' type='depth'>
          <update_rate>20</update_rate>
          <camera>
            <horizontal_fov>1.0472</horizontal_fov>
            <image>
              <width>640</width>
              <height>480</height>
              <format>R8G8B8</format>
            </image>
            <clip>
              <near>0.05</near>
              <far>100</far>
            </clip>
          </camera>
          <plugin name='kinect_controller' filename='libgazebo_ros_openni_kinect.so'>
            <robotNamespace/>
            <baseline>0.2</baseline>
            <alwaysOn>1</alwaysOn>
            <updateRate>20</updateRate>
            <cameraName>realsense/depth_camera</cameraName>
            <imageTopicName>color/image_raw</imageTopicName>
            <cameraInfoTopicName>color/camera_info</cameraInfoTopicName>
            <depthImageTopicName>depth/image_raw</depthImageTopicName>
            <depthImageInfoTopicName>depth/camera_info</depthImageInfoTopicName>
            <pointCloudTopicName>depth/points</pointCloudTopicName>
            <frameName>depth_camera_base</frameName>
            <pointCloudCutoff>0.05</pointCloudCutoff>
            <pointCloudCutoffMax>10</pointCloudCutoffMax>
            <distortionK1>0.00000001</distortionK1>
            <distortionK2>0.00000001</distortionK2>
            <distortionK3>0.00000001</distortionK3>
            <distortionT1>0.00000001</distortionT1>
            <distortionT2>0.00000001</distortionT2>
            <CxPrime>0</CxPrime>
            <Cx>0</Cx>
            <Cy>0</Cy>
            <focalLength>0</focalLength>
            <hackBaseline>0</hackBaseline>
          </plugin>
        </sensor>
        <pose relative_to='realsense_camera::__model__'>0 0 0 0 -0 0</pose>
      </link>
      <joint name='realsense_camera_joint' type='revolute'>
        <child>realsense_camera::link</child>
        <parent>base_link</parent>
        <axis>
          <xyz>0 0 1</xyz>
          <limit>
            <upper>0</upper>
            <lower>0</lower>
          </limit>
          <dynamics>
            <spring_reference>0</spring_reference>
            <spring_stiffness>0</spring_stiffness>
          </dynamics>
        </axis>
      </joint>
      <pose>0 0 0 0 -0 0</pose>
    </model>
    
  <actor name="actor">

    <plugin name="actor_collisions_plugin" filename="libActorCollisionsPlugin.so">
      <scaling collision="LHipJoint_LeftUpLeg_collision" scale="
        0.01
        0.001
        0.001
      "/>
      <scaling collision="LeftUpLeg_LeftLeg_collision" scale="
        8.0
        8.0
        1.0
      "/>
      <scaling collision="LeftLeg_LeftFoot_collision" scale="
        8.0
        8.0
        1.0
      "/>
      <scaling collision="LeftFoot_LeftToeBase_collision" scale="
        4.0
        4.0
        1.5
      "/>
      <scaling collision="RHipJoint_RightUpLeg_collision" scale="
        0.01
        0.001
        0.001
      "/>
      <scaling collision="RightUpLeg_RightLeg_collision" scale="
        8.0
        8.0
        1.0
      "/>
      <scaling collision="RightLeg_RightFoot_collision" scale="
        8.0
        8.0
        1.0
      "/>
      <scaling collision="RightFoot_RightToeBase_collision" scale="
        4.0
        4.0
        1.5
      "/>
      <scaling collision="LowerBack_Spine_collision" scale="
        12.0
        20.0
        5.0
      " pose="0.05 0 0 0 -0.2 0"/>
      <scaling collision="Spine_Spine1_collision" scale="
        0.01
        0.001
        0.001
      "/>
      <scaling collision="Neck_Neck1_collision" scale="
        0.01
        0.001
        0.001
      "/>
      <scaling collision="Neck1_Head_collision" scale="
        5.0
        5.0
        3.0
      "/>
      <scaling collision="LeftShoulder_LeftArm_collision" scale="
        0.01
        0.001
        0.001
      "/>
      <scaling collision="LeftArm_LeftForeArm_collision" scale="
        5.0
        5.0
        1.0
      "/>
      <scaling collision="LeftForeArm_LeftHand_collision" scale="
        5.0
        5.0
        1.0
      "/>
      <scaling collision="LeftFingerBase_LeftHandIndex1_collision" scale="
        4.0
        4.0
        3.0
      "/>
      <scaling collision="RightShoulder_RightArm_collision" scale="
        0.01
        0.001
        0.001
      "/>
      <scaling collision="RightArm_RightForeArm_collision" scale="
        5.0
        5.0
        1.0
      "/>
      <scaling collision="RightForeArm_RightHand_collision" scale="
        5.0
        5.0
        1.0
      "/>
      <scaling collision="RightFingerBase_RightHandIndex1_collision" scale="
        4.0
        4.0
        3.0
      "/>
    </plugin>
    <skin>
      <filename>walk.dae</filename>
      <scale>1.0</scale>
    </skin>
    <animation name="walking">
      <filename>walk.dae</filename>
      <scale>1.000000</scale>
      <interpolate_x>true</interpolate_x>
    </animation>
    <script>
      <loop>true</loop>
      <delay_start>0.000000</delay_start>
      <auto_start>true</auto_start>
      <trajectory id="0" type="walking">
        <waypoint>
          <time>0.000000</time>
          <pose>0.000000 1.000000 0.000000 0.000000 0.000000 0.000000</pose>
        </waypoint>
        <waypoint>
          <time>0.500000</time>
          <pose>0.195090 0.980785 0.000000 0.000000 0.000000 -0.196350</pose>
        </waypoint>
        <waypoint>
           <time>1.000000</time>
           <pose>0.382683 0.923880 0.000000 0.000000 0.000000 -0.392699</pose>
        </waypoint>
        <waypoint>
           <time>1.500000</time>
           <pose>0.555570 0.831470 0.000000 0.000000 0.000000 -0.589049</pose>
        </waypoint>
        <waypoint>
           <time>2.000000</time>
           <pose>0.707107 0.707107 0.000000 0.000000 0.000000 -0.785398</pose>
        </waypoint>
        <waypoint>
           <time>2.500000</time>
           <pose>0.831470 0.555570 0.000000 0.000000 0.000000 -0.981748</pose>
        </waypoint>
        <waypoint>
           <time>3.000000</time>
           <pose>0.923880 0.382683 0.000000 0.000000 0.000000 -1.178100</pose>
        </waypoint>
        <waypoint>
           <time>3.500000</time>
           <pose>0.980785 0.195090 0.000000 0.000000 0.000000 -1.374450</pose>
        </waypoint>
        <waypoint>
           <time>4.000000</time>
           <pose>1.000000 0.000000 0.000000 0.000000 0.000000 -1.570800</pose>
        </waypoint>
        <waypoint>
           <time>4.500000</time>
           <pose>0.980785 -0.195090 0.000000 0.000000 0.000000 -1.767150</pose>
        </waypoint>
        <waypoint>
           <time>5.000000</time>
           <pose>0.923880 -0.382683 0.000000 0.000000 0.000000 -1.963500</pose>
        </waypoint>
        <waypoint>
           <time>5.500000</time>
           <pose>0.831470 -0.555570 0.000000 0.000000 0.000000 -2.159840</pose>
        </waypoint>
        <waypoint>
           <time>6.000000</time>
           <pose>0.707107 -0.707107 0.000000 0.000000 0.000000 -2.356190</pose>
        </waypoint>
        <waypoint>
           <time>6.500000</time>
           <pose>0.555570 -0.831470 0.000000 0.000000 0.000000 -2.552540</pose>
        </waypoint>
        <waypoint>
           <time>7.500000</time>
           <pose>0.382683 -0.923880 0.000000 0.000000 0.000000 -2.748890</pose>
        </waypoint>
        <waypoint>
           <time>8.500000</time>
           <pose>0.195090 -0.980785 0.000000 0.000000 0.000000 -2.945240</pose>
        </waypoint>
        <waypoint>
           <time>9.500000</time>
           <pose>0.000000 -1.000000 0.000000 0.000000 0.000000 -3.141590</pose>
        </waypoint>
        <waypoint>
           <time>10.500000</time>
           <pose>-0.195090 -0.980785 0.000000 0.000000 0.000000 2.945245</pose>
        </waypoint>
        <waypoint>
           <time>11.500000</time>
           <pose>-0.382683 -0.923880 0.000000 0.000000 0.000000 2.748895</pose>
        </waypoint>
        <waypoint>
           <time>12.000000</time>
           <pose>-0.555570 -0.831470 0.000000 0.000000 0.000000 2.552545</pose>
        </waypoint>
        <waypoint>
           <time>12.500000</time>
           <pose>-0.707107 -0.707107 0.000000 0.000000 0.000000 2.356195</pose>
        </waypoint>
        <waypoint>
           <time>13.000000</time>
           <pose>-0.831470 -0.555570 0.000000 0.000000 0.000000 2.159845</pose>
        </waypoint>
        <waypoint>
           <time>13.500000</time>
           <pose>-0.923880 -0.382683 0.000000 0.000000 0.000000 1.963495</pose>
        </waypoint>
        <waypoint>
           <time>14.000000</time>
           <pose>-0.980785 -0.195090 0.000000 0.000000 0.000000 1.767145</pose>
        </waypoint>
        <waypoint>
           <time>14.500000</time>
           <pose>-1.000000 0.000000 0.000000 0.000000 0.000000 1.570795</pose>
        </waypoint>
        <waypoint>
           <time>15.000000</time>
           <pose>-0.980785 0.195090 0.000000 0.000000 0.000000 1.374445</pose>
        </waypoint>
        <waypoint>
           <time>15.500000</time>
           <pose>-0.923880 0.382683 0.000000 0.000000 0.000000 1.178095</pose>
        </waypoint>
        <waypoint>
           <time>16.000000</time>
           <pose>-0.831470 0.555570 0.000000 0.000000 0.000000 0.981745</pose>
        </waypoint>
        <waypoint>
           <time>16.500000</time>
           <pose>-0.707107 0.707107 0.000000 0.000000 0.000000 0.785395</pose>
        </waypoint>
        <waypoint>
           <time>17.000000</time>
           <pose>-0.555570 0.831470 0.000000 0.000000 0.000000 0.589045</pose>
        </waypoint>
        <waypoint>
           <time>17.500000</time>
           <pose>-0.382683 0.923880 0.000000 0.000000 0.000000 0.392695</pose>
        </waypoint>
        <waypoint>
           <time>18.000000</time>
           <pose>-0.195090 0.980785 0.000000 0.000000 0.000000 0.196345</pose>
        </waypoint>
      </trajectory>
    </script>
  </actor>

  </world>
</sdf>
